Workbook

Sheet README
A1: 2026 Tracking System (template for Google Sheets)
A3: How to use:
A4: 1) Import this .xlsx into Google Sheets (File → Import).
A5: 2) Your app/webapp should append rows into: Raw_Events (event logs) and Raw_Weekly (weekly inputs).
A6: 3) Maintain People list (or let the app create people and reference PersonID in Raw_Events).
A7: 4) Review Dashboard weekly; Monthly/Quarterly tabs support your review cadence.
A9: Data-entry principles:
A10: - Prefer event-based logging (multiple quick logs per day).
A11: - Weekly inputs are only: WorkHours + PersonalExpenses + ExcludedRenovationExpenses (+ optional NetWorth_RUB + notes).
A13: Key tabs:
A14: - Settings: targets and constants (blue cells are editable).
A15: - Raw_Events: event log (app writes here).
... A18: - Net worth KPI: fill Raw_Weekly → NetWorth_RUB (optional). Settings contains starting and target net worth.

Sheet Settings
A1: 2026 Tracking Targets & Constants
A3: Year | B3: 2026 | D3: Notes
A4: Year Start | B4: 46023 | D4: Edit blue cells only.
A5: Year End | B5: 46387
A6: Days in year | B6: =B5-B4+1
A7: As-of date (for dashboard) | B7: =TODAY()
A8: Max Raw_Events rows (for formulas) | B8: 8000
A9: Targets (from plan)
A10: Metric | B10: Time scale | C10: Target | D10: Unit | E10: Plan reference / notes
A11: Expenses (personal, excl. renovation) | B11: Annual cap | C11: 9000000 | D11: RUB | E11: Total expenses <9m; excludes ex-partner renovation
A12: Expenses (personal) | B12: Weekly cap | C12: 175000 | D12: RUB | E12: Weekly expenses <175k
A13: Work hours | B13: Weekly target | C13: 55 | D13: hours | E13: Work hours <55/week
A14: Deal spike threshold | B14: Weekly trigger | C14: 60 | D14: hours | E14: Busy Week Protocol triggers >60h
A15: Mindfulness | B15: Weekly target | C15: 100 | D15: minutes | E15: Mindfulness 100 min/week
A16: Net worth (RUB) | B16: Year-end target | C16: 120000000 | D16: RUB | E16: Desired net worth outcome: RUB >120m (starting: ca. RUB 88m)
A17: Posture training (15 min session) | B17: Daily target | C17: 1 | D17: session | E17: 1 session/day; session = 15 min
A18: Sleep | B18: Average | C18: 7.5 | D18: hours/day | E18: Sleep 7:30 average
A19: Alcohol | B19: Average cap | C19: 0.4 | D19: std drinks/day | E19: Alcohol <0.4 average
A20: Cigarettes | B20: Annual cap | C20: 100 | D20: cigarettes | E20: Cigarettes <100/year
A21: Unhealthy meals & snacks | B21: Annual cap | C21: 150 | D21: count | E21: Unhealthy meals/snacks <150/year
A22: Workouts skipped | B22: Annual cap | C22: 8 | D22: count | E22: Workouts skipped <8/year
... A42: Net worth starting (RUB) | B42: Baseline | C42: 88000000 | D42: RUB | E42: Starting net worth: ca. RUB 88m (plan baseline)

Sheet Metric_Catalog
A1: Metric Catalog (used by app and validations)
A2: MetricCode | B2: MetricName | C2: Category | D2: Storage | E2: DefaultUnit | F2: ValueType | G2: NeedsPerson? | H2: NeedsTemplate? | I2: DefaultStep | J2: Presets | K2: Active? | L2: Notes
A3: SLEEP_HOURS | B3: Sleep hours | C3: Health | D3: Event | E3: hours | F3: number | G3: No | H3: No | I3: 0.25 | J3: 6,7,7.5,8,9 | K3: 1 | L3: Can be imported from Apple Health; use occurred_at as night end time or morning.
A4: POSTURE_SESSION | B4: Posture training session | C4: Health | D4: Event | E4: session | F4: boolean | G4: No | H4: No | I4: 1 | J4: 1 | K4: 1 | L4: 1 session assumed = 15 min per plan.
A5: WORKOUT | B5: Strength workout session | C5: Health | D5: Event | E5: count | F5: boolean | G5: No | H5: No | I5: 1 | K5: 1 | L5: Workout completed (optional; helps context).
A6: WORKOUT_SKIPPED | B6: Workout skipped | C6: Health | D6: Event | E6: count | F6: boolean | G6: No | H6: No | I6: 1 | K6: 1 | L6: Log when a planned session is skipped (excluding medical if desired via tag).
A7: LEAN_BODY_WEIGHT_KG | B7: Lean body weight (kg) | C7: Health | D7: Body | E7: kg | F7: number | G7: No | H7: No | I7: 0.1 | K7: 1 | L7: Optional body metric snapshot; used for +4kg target.
A8: UNHEALTHY_MEAL | B8: Unhealthy meal/snack | C8: Health | D8: Event | E8: count | F8: number | G8: No | H8: No | I8: 1 | J8: 1 | K8: 1 | L8: Unhealthy defined in plan; log as count.
A9: CIGARETTES | B9: Cigarettes smoked | C9: Health | D9: Event | E9: count | F9: number | G9: No | H9: No | I9: 1 | J9: 1,2,3,5,10 | K9: 1 | L9: Annual cap <100.
A10: ALCOHOL | B10: Alcohol servings (uses template) | C10: Health | D10: Event | E10: servings | F10: number | G10: No | H10: Yes | I10: 1 | J10: 0.5,1,2,3 | K10: 1 | L10: Value is servings; StdDrinks computed using Drink_Templates.
A11: MINDFULNESS_MIN | B11: Mindfulness minutes | C11: Mindfulness | D11: Event | E11: minutes | F11: number | G11: No | H11: No | I11: 5 | J11: 5,10,15,20,30 | K11: 1 | L11: Weekly target 100 min; 4+ days/week.
A12: TRAINING_MIN | B12: Public speaking/presentation training | C12: Career | D12: Event | E12: minutes | F12: number | G12: No | H12: No | I12: 15 | J12: 15,30,45,60,90 | K12: 1 | L12: Counts toward 100h annual training.
A13: DICTION_TRAINING_MIN | B13: Diction / speech therapy training minutes | C13: Career | D13: Event | E13: minutes | F13: number | G13: No | H13: No | I13: 15 | J13: 15,30,45,60 | K13: 1 | L13: Speech therapist sessions; supports diction improvement metric.
A14: VOICE_SAMPLE | B14: Voice sample recording | C14: Career | D14: Event | E14: count | F14: boolean | G14: No | H14: No | I14: 1 | K14: 1 | L14: Log when you record baseline or periodic samples.
A15: BOOK_FINISHED | B15: Book finished | C15: Career | D15: Event | E15: count | F15: boolean | G15: No | H15: No | I15: 1 | K15: 1 | L15: Counts toward 15 books annual.
A16: PRO_CONTACT_ADDED | B16: New professional contact added | C16: Career | D16: Event | E16: count | F16: boolean | G16: Yes | H16: No | I16: 1 | K16: 1 | L16: Requires PersonID (Type=Pro).
A17: ORIGINATION_ACTION | B17: Origination action (weekly) | C17: Career | D17: Event | E17: count | F17: boolean | G17: No | H17: No | I17: 1 | K17: 1 | L17: Plan metric: at least 1 per week; use tags for subtype (chat/memo/pitch).
A18: INITIATIVE_IDEA | B18: Initiative idea captured | C18: Career | D18: Event | E18: count | F18: boolean | G18: No | H18: No | I18: 1 | K18: 1 | L18: Used to maintain list of 10 initiative ideas (project hygiene).
A19: STAKEHOLDER_CHAT | B19: Stakeholder conversation | C19: Career | D19: Event | E19: count | F19: boolean | G19: Yes | H19: No | I19: 1 | K19: 1 | L19: Project activity; can be counted toward origination actions.
A20: MEMO_WRITTEN | B20: Written memo | C20: Career | D20: Event | E20: count | F20: boolean | G20: No | H20: No | I20: 1 | K20: 1 | L20: Project output; quarterly minimum.
A21: INITIATIVE_PRESENTED_VP | B21: Initiative presented to VP | C21: Career | D21: Event | E21: count | F21: boolean | G21: No | H21: No | I21: 1 | K21: 1 | L21: Annual target 2.
A22: SOCIAL_MEET | B22: Informal social meeting | C22: Social | D22: Event | E22: count | F22: boolean | G22: Yes | H22: No | I22: 1 | K22: 1 | L22: Informal only; use PersonID (Type=Social).
A23: COMMUNITY_SESSION | B23: Community session attended | C23: Social | D23: Event | E23: count | F23: boolean | G23: No | H23: No | I23: 1 | K23: 1 | L23: Use tags to identify community; used for Q1 milestone.
A24: HOSTED_EVENT | B24: Hosted/organized social event | C24: Social | D24: Event | E24: count | F24: boolean | G24: No | H24: No | I24: 1 | K24: 1 | L24: Counts toward hosting milestones.
A25: DATE | B25: Date | C25: Dating | D25: Event | E25: count | F25: boolean | G25: Yes | H25: No | I25: 1 | K25: 1 | L25: Use PersonID (Type=Romance).
... A28: RELATIONSHIP_END | B28: Relationship end | C28: Dating | D28: Event | E28: count | F28: boolean | G28: Yes | H28: No | I28: 1 | K28: 1 | L28: Helper for duration/stop condition.
A29: IDEA | B29: Idea captured | C29: Creativity | D29: Event | E29: count | F29: number | G29: No | H29: No | I29: 1 | J29: 1,2,3,5,10 | K29: 1 | L29: Weekly target 10; annual 500.
A30: IDEA_STAR | B30: Starred idea of the week | C30: Creativity | D30: Event | E30: count | F30: boolean | G30: No | H30: No | I30: 1 | K30: 1 | L30: Supports weekly 20-min review protocol.
A31: NEW_ACTIVITY | B31: New activity tried | C31: Creativity | D31: Event | E31: count | F31: boolean | G31: No | H31: No | I31: 1 | K31: 1 | L31: Annual target 12.
A32: TRAVEL_NIGHT | B32: Travel night | C32: Creativity | D32: Event | E32: nights | F32: number | G32: No | H32: No | I32: 1 | J32: 1 | K32: 1 | L32: Annual target >10 nights (tracked as 11+).
A33: COOKING_SESSION | B33: Cooking session (anchor hobby) | C33: Creativity | D33: Event | E33: count | F33: boolean | G33: No | H33: No | I33: 1 | K33: 1 | L33: Anchor hobby.
A34: PISTOL_SHOOTING_SESSION | B34: Pistol shooting session (anchor hobby) | C34: Creativity | D34: Event | E34: count | F34: boolean | G34: No | H34: No | I34: 1 | K34: 1 | L34: Anchor hobby.
A35: WORKHOURS_WEEKLY | B35: Work hours (weekly) | C35: Work/Finance | D35: Weekly | E35: hours | F35: number | G35: No | H35: No | I35: 0.5 | K35: 1 | L35: Entered in Raw_Weekly; used for <55 goal and busy-week trigger.
A36: EXPENSES_PERSONAL_RUB | B36: Personal expenses (weekly) | C36: Work/Finance | D36: Weekly | E36: RUB | F36: number | G36: No | H36: No | I36: 1000 | K36: 1 | L36: Entered in Raw_Weekly; excludes renovation for annual cap.
A37: EXCLUDED_RENOVATION_RUB | B37: Excluded renovation expenses (weekly) | C37: Work/Finance | D37: Weekly | E37: RUB | F37: number | G37: No | H37: No | I37: 1000 | K37: 1 | L37: Excluded from annual expense cap reporting.
A38: NETWORTH_RUB | B38: Net worth snapshot (RUB) | C38: Work/Finance | D38: Weekly | E38: RUB | F38: number | G38: No | H38: No | I38: 100000 | K38: 1 | L38: Optional weekly snapshot in Raw_Weekly.
A39: DEALSPIKE_FLAG | B39: Deal spike flag | C39: Work/Finance | D39: Weekly | E39: boolean | F39: boolean | G39: No | H39: No | I39: 1 | J39: 0,1 | K39: 1 | L39: Optional; if 1 then Busy Week protocol applies even if hours<60.
A40: DEEP_WORK_HOURS | B40: Deep work hours | C40: Career | D40: Event | E40: hours | F40: number | G40: No | H40: No | I40: 0.5 | K40: 1 | L40: Future-vision metric; no 2026 target defined.
A41: PARTNER_QUALITY_TIME | B41: Quality time with partner | C41: Dating | D41: Event | E41: count | F41: boolean | G41: Yes | H41: No | I41: 1 | K41: 1 | L41: Future-vision metric; optional once in relationship.
A42: RELEVANT_CONTACT_APPROACH | B42: Relevant contact approached | C42: Career | D42: Event | E42: count | F42: boolean | G42: Yes | H42: No | I42: 1 | K42: 1 | L42: Future-vision metric; optional.
...

Sheet Goal_Catalog
A1: Goal Catalog (config-driven; edit targets here)
A2: GoalID | B2: GoalName | C2: MetricCode | D2: TargetType | E2: TargetValue | F2: TargetUnit | G2: TimeScale | H2: StartDate | I2: EndDate | J2: Active? | K2: StopConditionType | L2: StopConditionValue | M2: Thresholds/Rules | N2: Notes
A3: G_EXPENSES_Y | B3: Annual expenses cap (excl renovation) | C3: EXPENSES_PERSONAL_RUB | D3: max | E3: =Settings!$C$11 | F3: RUB | G3: yearly | H3: =Settings!$B$4 | I3: =Settings!$B$5 | J3: 1 | M3: Annual cap excludes Raw_Weekly ExcludedRenovation_RUB. | N3: Uses Weekly expenses rollup.
A4: G_EXPENSES_W | B4: Weekly expenses cap | C4: EXPENSES_PERSONAL_RUB | D4: max | E4: =Settings!$C$12 | F4: RUB | G4: weekly | H4: =Settings!$B$4 | I4: =Settings!$B$5 | J4: 1
A5: G_WORKHOURS_W | B5: Work hours cap | C5: WORKHOURS_WEEKLY | D5: max | E5: =Settings!$C$13 | F5: hours | G5: weekly | H5: =Settings!$B$4 | I5: =Settings!$B$5 | J5: 1 | M5: Busy week trigger at Settings!$C$14 or DealSpikeFlag=1.
A6: G_MINDFUL_W_MIN | B6: Mindfulness minutes/week | C6: MINDFULNESS_MIN | D6: min | E6: =Settings!$C$15 | F6: min | G6: weekly | H6: =Settings!$B$4 | I6: =Settings!$B$5 | J6: 1 | M6: Also track days/week >=4.
A7: G_MINDFUL_W_DAYS | B7: Mindfulness days/week | C7: MINDFULNESS_MIN | D7: min_days | E7: 4 | F7: days | G7: weekly | H7: =Settings!$B$4 | I7: =Settings!$B$5 | J7: 1 | M7: Day counts as >=1 minute.
A8: G_POSTURE_D | B8: Posture daily session | C8: POSTURE_SESSION | D8: min | E8: =Settings!$C$17 | F8: sessions | G8: daily | H8: =Settings!$B$4 | I8: =Settings!$B$5 | J8: 1 | M8: 1 session/day (each session = 15 min per plan).
A9: G_SLEEP_AVG | B9: Sleep average | C9: SLEEP_HOURS | D9: avg_min | E9: =Settings!$C$18 | F9: hours/day | G9: yearly | H9: =Settings!$B$4 | I9: =Settings!$B$5 | J9: 1 | M9: Uses occurred_at date; set occurred_at to morning for each sleep entry.
A10: G_ALCOHOL_AVG | B10: Alcohol average cap | C10: ALCOHOL | D10: avg_max | E10: =Settings!$C$19 | F10: std drinks/day | G10: yearly | H10: =Settings!$B$4 | I10: =Settings!$B$5 | J10: 1 | M10: Uses implied cap line: avg*days elapsed.
A11: G_CIGS_Y | B11: Cigarettes annual cap | C11: CIGARETTES | D11: max | E11: =Settings!$C$20 | F11: cigs | G11: yearly | H11: =Settings!$B$4 | I11: =Settings!$B$5 | J11: 1
A12: G_UNHEALTHY_Y | B12: Unhealthy meals/snacks annual cap | C12: UNHEALTHY_MEAL | D12: max | E12: =Settings!$C$21 | F12: count | G12: yearly | H12: =Settings!$B$4 | I12: =Settings!$B$5 | J12: 1
A13: G_WORKOUTSKIP_Y | B13: Workout skips annual cap | C13: WORKOUT_SKIPPED | D13: max | E13: =Settings!$C$22 | F13: count | G13: yearly | H13: =Settings!$B$4 | I13: =Settings!$B$5 | J13: 1
A14: G_LBW_GAIN | B14: Lean body weight gain | C14: LEAN_BODY_WEIGHT_KG | D14: delta_min | E14: =Settings!$C$23 | F14: kg | G14: yearly | H14: =Settings!$B$4 | I14: =Settings!$B$5 | J14: 1 | M14: Delta = latest - baseline (first entry in year).
A15: G_BOOKS_Y | B15: Books read | C15: BOOK_FINISHED | D15: min | E15: =Settings!$C$24 | F15: books | G15: yearly | H15: =Settings!$B$4 | I15: =Settings!$B$5 | J15: 1
A16: G_TRAINING_Y | B16: Training hours | C16: TRAINING_MIN | D16: min | E16: =Settings!$C$25 | F16: hours | G16: yearly | H16: =Settings!$B$4 | I16: =Settings!$B$5 | J16: 1 | M16: Stored in minutes in Raw_Events; rollups convert to hours. Includes DICTION_TRAINING_MIN.
A17: G_PROCONTACTS_Y | B17: New professional contacts | C17: PRO_CONTACT_ADDED | D17: min | E17: =Settings!$C$26 | F17: people | G17: yearly | H17: =Settings!$B$4 | I17: =Settings!$B$5 | J17: 1 | M17: Count distinct people with >=1 PRO_CONTACT_ADDED.
A18: G_VP_PRES_Y | B18: Initiatives presented to VP | C18: INITIATIVE_PRESENTED_VP | D18: min | E18: =Settings!$C$27 | F18: count | G18: yearly | H18: =Settings!$B$4 | I18: =Settings!$B$5 | J18: 1
A19: G_ORIG_W | B19: Origination actions/week | C19: ORIGINATION_ACTION | D19: min | E19: 1 | F19: count | G19: weekly | H19: =Settings!$B$4 | I19: =Settings!$B$5 | J19: 1 | M19: Treat STAKEHOLDER_CHAT / MEMO_WRITTEN / VP_PRESENT as origination too (see Weekly_Agg).
A20: G_FRIENDS_2P | B20: People met 2+ times (social) | C20: SOCIAL_MEET | D20: min_unique_threshold | E20: =Settings!$C$35 | F20: people | G20: yearly | H20: =Settings!$B$4 | I20: =Settings!$B$5 | J20: 1 | M20: Computed from People.Meetings2026>=2 for Type=Social.
A21: G_FRIENDS_5P | B21: People met 5+ times (social) | C21: SOCIAL_MEET | D21: min_unique_threshold | E21: =Settings!$C$36 | F21: people | G21: yearly | H21: =Settings!$B$4 | I21: =Settings!$B$5 | J21: 1 | M21: Computed from People.Meetings2026>=5 for Type=Social.
A22: G_DATES_M | B22: New dates/month | C22: DATE | D22: min | E22: =Settings!$C$37 | F22: dates | G22: monthly | H22: =DATE(2026,6,1) | I22: =Settings!$B$5 | J22: 1 | K22: stop_on_relationship_start | L22: RELATIONSHIP_START | M22: Monthly target applies from June 2026; 0 target before. Stop when a RELATIONSHIP_START is logged (assumption).
A23: G_SEXPARTNERS_Y | B23: New sex partners | C23: SEX | D23: min_unique | E23: =Settings!$C$38 | F23: people | G23: yearly | H23: =Settings!$B$4 | I23: =Settings!$B$5 | J23: 1 | K23: stop_on_relationship_start | L23: RELATIONSHIP_START | M23: Stop when RELATIONSHIP_START logged (assumption).
A24: G_IDEAS_W | B24: Ideas/week | C24: IDEA | D24: min | E24: =Settings!$C$34 | F24: ideas | G24: weekly | H24: =Settings!$B$4 | I24: =Settings!$B$5 | J24: 1 | M24: Busy-week floor applies.
A25: G_IDEAS_Y | B25: Ideas annual | C25: IDEA | D25: min | E25: =Settings!$C$33 | F25: ideas | G25: yearly | H25: =Settings!$B$4 | I25: =Settings!$B$5 | J25: 1
A26: G_IDEA_REVIEW_W | B26: Star top idea/week | C26: IDEA_STAR | D26: min | E26: 1 | F26: count | G26: weekly | H26: =Settings!$B$4 | I26: =Settings!$B$5 | J26: 1 | M26: Protocol: weekly 20-minute review.
A27: G_NEWACT_Y | B27: New activities tried | C27: NEW_ACTIVITY | D27: min | E27: =Settings!$C$31 | F27: count | G27: yearly | H27: =Settings!$B$4 | I27: =Settings!$B$5 | J27: 1 | K27: paused_during_busy_week | L27: BusyWeek | M27: Paused in busy weeks per protocol.
A28: G_TRAVEL_Y | B28: Travel nights | C28: TRAVEL_NIGHT | D28: min | E28: =Settings!$C$32 | F28: nights | G28: yearly | H28: =Settings!$B$4 | I28: =Settings!$B$5 | J28: 1
A29: G_ANCHOR_Q | B29: Anchor hobby sessions/quarter (cooking+pistol) | C29: COOKING_SESSION | D29: min_combo | E29: 12 | F29: sessions | G29: quarterly | H29: =Settings!$B$4 | I29: =Settings!$B$5 | J29: 1 | M29: Counts COOKING_SESSION + PISTOL_SHOOTING_SESSION within quarter. | N29: Milestone-driven.
A30: G_NETWORTH_Y | B30: Net worth year-end target | C30: NETWORTH_RUB | D30: min | E30: =Settings!$C$16 | F30: RUB | G30: yearly | H30: =Settings!$B$4 | I30: =Settings!$B$5 | J30: 1 | M30: Uses latest NetWorth_RUB snapshot in Raw_Weekly.
A31: G_RELATIONSHIP_3M | B31: New romantic relationship duration >3 months | C31: RELATIONSHIP_START | D31: min_duration_days | E31: 90 | F31: days | G31: yearly | H31: =Settings!$B$4 | I31: =Settings!$B$5 | J31: 1 | M31: Derived: duration from latest RELATIONSHIP_START to RELATIONSHIP_END (or as-of) in Dashboard.

Sheet Tile_Catalog
A1: Tile Catalog (app home screen configuration)
A2: TileID | B2: DisplayName | C2: MetricCode | D2: WidgetType | E2: DefaultValue | F2: Step | G2: Unit | H2: NeedsPerson? | I2: NeedsTemplate? | J2: Presets | K2: Order | L2: Active? | M2: Notes
A3: T_IDEA | B3: Idea +1 | C3: IDEA | D3: stepper | E3: 1 | F3: 1 | G3: count | H3: No | I3: No | J3: 1,2,3,5,10 | K3: 1 | L3: 1 | M3: Primary capture tile; supports adding multiple at once.
A4: T_IDEA_STAR | B4: Star top idea | C4: IDEA_STAR | D4: toggle | E4: 1 | F4: 1 | G4: count | H4: No | I4: No | K4: 2 | L4: 1 | M4: Weekly review habit.
A5: T_CIGS | B5: Cigarettes | C5: CIGARETTES | D5: stepper | E5: 1 | F5: 1 | G5: cigs | H5: No | I5: No | J5: 1,2,3,5 | K5: 3 | L5: 1
A6: T_ALCOHOL | B6: Alcohol (template) | C6: ALCOHOL | D6: template_stepper | E6: 1 | F6: 0.5 | G6: servings | H6: No | I6: Yes | K6: 4 | L6: 1 | M6: Choose DrinkTemplate then servings; StdDrinks computed in sheet.
A7: T_MINDFUL | B7: Mindfulness | C7: MINDFULNESS_MIN | D7: minute_picker | E7: 10 | F7: 5 | G7: min | H7: No | I7: No | J7: 5,10,15,20,30 | K7: 5 | L7: 1 | M7: Can be automated from Apple Health if available.
A8: T_POSTURE | B8: Posture (done) | C8: POSTURE_SESSION | D8: toggle | E8: 1 | F8: 1 | G8: session | H8: No | I8: No | J8: 1 | K8: 6 | L8: 1
A9: T_SLEEP | B9: Sleep | C9: SLEEP_HOURS | D9: duration_picker | E9: 7.5 | F9: 0.25 | G9: hours | H9: No | I9: No | J9: 6,7,7.5,8,9 | K9: 7 | L9: 1 | M9: Prefer automation from Apple Health; fallback manual.
A10: T_WORKOUT | B10: Workout done | C10: WORKOUT | D10: toggle | E10: 1 | F10: 1 | G10: count | H10: No | I10: No | K10: 8 | L10: 1 | M10: Optional.
A11: T_WORKOUT_SKIP | B11: Workout skipped | C11: WORKOUT_SKIPPED | D11: toggle | E11: 1 | F11: 1 | G11: count | H11: No | I11: No | K11: 9 | L11: 1
A12: T_UNHEALTHY | B12: Unhealthy meal/snack | C12: UNHEALTHY_MEAL | D12: toggle | E12: 1 | F12: 1 | G12: count | H12: No | I12: No | K12: 10 | L12: 1
A13: T_SOCIAL | B13: Social meet | C13: SOCIAL_MEET | D13: person_toggle | E13: 1 | F13: 1 | G13: count | H13: Yes | I13: No | J13: favorites | K13: 11 | L13: 1 | M13: Person picker required.
A14: T_COMMUNITY | B14: Community session | C14: COMMUNITY_SESSION | D14: tag_toggle | E14: 1 | F14: 1 | G14: count | H14: No | I14: No | J14: community:<name> | K14: 12 | L14: 1 | M14: Tag should include community:<name> for reporting.
A15: T_HOST | B15: Hosted event | C15: HOSTED_EVENT | D15: toggle | E15: 1 | F15: 1 | G15: count | H15: No | I15: No | K15: 13 | L15: 1
A16: T_DATE | B16: Date | C16: DATE | D16: person_toggle | E16: 1 | F16: 1 | G16: count | H16: Yes | I16: No | K16: 14 | L16: 1
A17: T_SEX | B17: Sex | C17: SEX | D17: person_toggle | E17: 1 | F17: 1 | G17: count | H17: Yes | I17: No | K17: 15 | L17: 1
A18: T_REL_START | B18: Relationship start | C18: RELATIONSHIP_START | D18: person_toggle | E18: 1 | F18: 1 | G18: count | H18: Yes | I18: No | K18: 16 | L18: 1 | M18: Stop condition for dating goals (assumption).
A19: T_REL_END | B19: Relationship end | C19: RELATIONSHIP_END | D19: person_toggle | E19: 1 | F19: 1 | G19: count | H19: Yes | I19: No | K19: 17 | L19: 1
A20: T_TRAIN | B20: Training session | C20: TRAINING_MIN | D20: minute_picker | E20: 60 | F20: 15 | G20: min | H20: No | I20: No | J20: 15,30,45,60,90 | K20: 18 | L20: 1
A21: T_VOICE | B21: Voice sample | C21: VOICE_SAMPLE | D21: toggle | E21: 1 | F21: 1 | G21: count | H21: No | I21: No | K21: 19 | L21: 1
A22: T_BOOK | B22: Book finished | C22: BOOK_FINISHED | D22: toggle | E22: 1 | F22: 1 | G22: count | H22: No | I22: No | K22: 20 | L22: 1
A23: T_ORIG | B23: Origination action | C23: ORIGINATION_ACTION | D23: toggle | E23: 1 | F23: 1 | G23: count | H23: No | I23: No | J23: stakeholder_chat,memo,pitch | K23: 21 | L23: 1 | M23: Use tags for subtype.
A24: T_PRO_CONTACT | B24: Add pro contact | C24: PRO_CONTACT_ADDED | D24: person_toggle | E24: 1 | F24: 1 | G24: count | H24: Yes | I24: No | K24: 22 | L24: 1
A25: T_STAKE_CHAT | B25: Stakeholder chat | C25: STAKEHOLDER_CHAT | D25: person_toggle | E25: 1 | F25: 1 | G25: count | H25: Yes | I25: No | K25: 23 | L25: 1 | M25: Optional detail beyond ORIGINATION_ACTION.
A26: T_MEMO | B26: Memo written | C26: MEMO_WRITTEN | D26: toggle | E26: 1 | F26: 1 | G26: count | H26: No | I26: No | K26: 24 | L26: 1
A27: T_VP_PITCH | B27: Presented to VP | C27: INITIATIVE_PRESENTED_VP | D27: toggle | E27: 1 | F27: 1 | G27: count | H27: No | I27: No | K27: 25 | L27: 1
A28: T_INIT_IDEA | B28: Initiative idea | C28: INITIATIVE_IDEA | D28: toggle | E28: 1 | F28: 1 | G28: count | H28: No | I28: No | K28: 26 | L28: 1
A29: T_NEW_ACT | B29: New activity tried | C29: NEW_ACTIVITY | D29: toggle | E29: 1 | F29: 1 | G29: count | H29: No | I29: No | K29: 27 | L29: 1
A30: T_TRAVEL | B30: Travel night(s) | C30: TRAVEL_NIGHT | D30: stepper | E30: 1 | F30: 1 | G30: nights | H30: No | I30: No | J30: 1,2,3,5 | K30: 28 | L30: 1
A31: T_COOK | B31: Cooking session | C31: COOKING_SESSION | D31: toggle | E31: 1 | F31: 1 | G31: count | H31: No | I31: No | K31: 29 | L31: 1
A32: T_PISTOL | B32: Pistol shooting | C32: PISTOL_SHOOTING_SESSION | D32: toggle | E32: 1 | F32: 1 | G32: count | H32: No | I32: No | K32: 30 | L32: 1
A33: T_DEEP_WORK | B33: Deep work hours | C33: DEEP_WORK_HOURS | D33: duration_picker | E33: 1 | F33: 0.5 | G33: hours | H33: No | I33: No | J33: 0.5,1,2,3 | K33: 31 | L33: 1 | M33: Log focused deep work time.
A34: T_EDU_HOURS | B34: Education hours | C34: EDUCATION_HOURS | D34: duration_picker | E34: 1 | F34: 0.5 | G34: hours | H34: No | I34: No | J34: 0.5,1,2,3 | K34: 32 | L34: 1 | M34: Learning / study time.
A35: T_PARTNER_QT | B35: Partner quality time | C35: PARTNER_QUALITY_TIME | D35: toggle | E35: 1 | F35: 1 | G35: count | H35: No | I35: No | K35: 33 | L35: 1 | M35: Quality time event.
A36: T_HOBBY_HOURS | B36: Hobby hours | C36: HOBBY_HOURS | D36: duration_picker | E36: 1 | F36: 0.5 | G36: hours | H36: No | I36: No | J36: 0.5,1,2,3 | K36: 34 | L36: 1 | M36: Hobby time.
A37: T_INVEST_COVER | B37: Investment coverage % | C37: INVESTMENT_COVERAGE | D37: stepper | E37: 1 | F37: 1 | G37: % | H37: No | I37: No | J37: 25,50,75,100 | K37: 35 | L37: 1 | M37: Percent of expenses covered by investment income.
A38: T_REL_CONTACT | B38: Relevant contact approached | C38: RELEVANT_CONTACT_APPROACH | D38: person_toggle | E38: 1 | F38: 1 | G38: count | H38: Yes | I38: No | K38: 36 | L38: 1 | M38: Log meaningful outreach to a relevant contact.
A39: T_EXERCISE_RESULT | B39: Exercise result | C39: EXERCISE_RESULT_KG | D39: stepper | E39: 2.5 | F39: 2.5 | G39: kg | H39: No | I39: No | J39: 2.5,5,10,20 | K39: 37 | L39: 1 | M39: Log key exercise result (kg).
A40: T_ACTIVITY_CANCEL | B40: Planned activity cancelled | C40: ACTIVITY_CANCELLED | D40: toggle | E40: 1 | F40: 1 | G40: count | H40: No | I40: No | K40: 38 | L40: 1 | M40: Use when canceling a planned activity.
...

Sheet Drink_Templates
A1: Drink Templates (for ALCOHOL logging; app should compute StdDrinks)
A2: DrinkTemplateID | B2: Name | C2: Category | D2: Volume_ml | E2: ABV | F2: Ethanol_g | G2: StdDrinks(14g)
A3: BEER_330_5 | B3: Beer 330ml (5%) | C3: Beer | D3: 330 | E3: 5 | F3: 13 | G3: 0.93
A4: BEER_500_5 | B4: Beer 500ml (5%) | C4: Beer | D4: 500 | E4: 5 | F4: 19.7 | G4: 1.41
A5: WINE_125_12_5 | B5: Wine 125ml (12.5%) | C5: Wine | D5: 125 | E5: 12.5 | F5: =F6/150*125 | G5: =G6/150*125
A6: WINE_150_12_5 | B6: Wine 150ml (12.5%) | C6: Wine | D6: 150 | E6: 12.5 | F6: 14.8 | G6: 1.06
A7: WINE_200_12_5 | B7: Wine 200ml (12.5%) | C7: Wine | D7: 200 | E7: 12.5 | F7: 19.7 | G7: 1.41
A8: SPIRITS_50_40 | B8: Spirits 50ml (40%) | C8: Spirits | D8: 50 | E8: 40 | F8: 15.8 | G8: 1.13
A9: SPIRITS_100_40 | B9: Spirits 100ml (40%) | C9: Spirits | D9: 100 | E9: 40 | F9: 31.6 | G9: 2.25
A10: COCKTAIL_STD | B10: Cocktail (default) | C10: Cocktail | D10: 150 | E10: 15 | F10: 17.8 | G10: 1.27

Sheet People
A1: People (for Social / Professional / Romance tracking)
A2: PersonID | B2: Name | C2: Type | D2: FirstMet | E2: Notes | F2: Meetings2026 | G2: Dates2026 | H2: Sex2026 | I2: ProContacts2026
A3: P0001 | B3: (example) Alex | C3: Social | D3: 46027 | F3: =IF($A3="","",COUNTIFS(Raw_Events!$G:$G,"SOCIAL_MEET",Raw_Events!$J:$J,$A3,Raw_Events!$C:$C,">="&Settings!$B$4,Raw_Events!$C:$C,"<="&Settings!$B$5)) | G3: =IF($A3="","",COUNTIFS(Raw_Events!$G:$G,"DATE",Raw_Events!$J:$J,$A3,Raw_Events!$C:$C,">="&Settings!$B$4,Raw_Events!$C:$C,"<="&Settings!$B$5)) | H3: =IF($A3="","",COUNTIFS(Raw_Events!$G:$G,"SEX",Raw_Events!$J:$J,$A3,Raw_Events!$C:$C,">="&Settings!$B$4,Raw_Events!$C:$C,"<="&Settings!$B$5)) | I3: =IF($A3="","",COUNTIFS(Raw_Events!$G:$G,"PRO_CONTACT_ADDED",Raw_Events!$J:$J,$A3,Raw_Events!$C:$C,">="&Settings!$B$4,Raw_Events!$C:$C,"<="&Settings!$B$5))
F4: =IF($A4="","",COUNTIFS(Raw_Events!$G:$G,"SOCIAL_MEET",Raw_Events!$J:$J,$A4,Raw_Events!$C:$C,">="&Settings!$B$4,Raw_Events!$C:$C,"<="&Settings!$B$5)) | G4: =IF($A4="","",COUNTIFS(Raw_Events!$G:$G,"DATE",Raw_Events!$J:$J,$A4,Raw_Events!$C:$C,">="&Settings!$B$4,Raw_Events!$C:$C,"<="&Settings!$B$5)) | H4: =IF($A4="","",COUNTIFS(Raw_Events!$G:$G,"SEX",Raw_Events!$J:$J,$A4,Raw_Events!$C:$C,">="&Settings!$B$4,Raw_Events!$C:$C,"<="&Settings!$B$5)) | I4: =IF($A4="","",COUNTIFS(Raw_Events!$G:$G,"PRO_CONTACT_ADDED",Raw_Events!$J:$J,$A4,Raw_Events!$C:$C,">="&Settings!$B$4,Raw_Events!$C:$C,"<="&Settings!$B$5))
F5: =IF($A5="","",COUNTIFS(Raw_Events!$G:$G,"SOCIAL_MEET",Raw_Events!$J:$J,$A5,Raw_Events!$C:$C,">="&Settings!$B$4,Raw_Events!$C:$C,"<="&Settings!$B$5)) | G5: =IF($A5="","",COUNTIFS(Raw_Events!$G:$G,"DATE",Raw_Events!$J:$J,$A5,Raw_Events!$C:$C,">="&Settings!$B$4,Raw_Events!$C:$C,"<="&Settings!$B$5)) | H5: =IF($A5="","",COUNTIFS(Raw_Events!$G:$G,"SEX",Raw_Events!$J:$J,$A5,Raw_Events!$C:$C,">="&Settings!$B$4,Raw_Events!$C:$C,"<="&Settings!$B$5)) | I5: =IF($A5="","",COUNTIFS(Raw_Events!$G:$G,"PRO_CONTACT_ADDED",Raw_Events!$J:$J,$A5,Raw_Events!$C:$C,">="&Settings!$B$4,Raw_Events!$C:$C,"<="&Settings!$B$5))
F6: =IF($A6="","",COUNTIFS(Raw_Events!$G:$G,"SOCIAL_MEET",Raw_Events!$J:$J,$A6,Raw_Events!$C:$C,">="&Settings!$B$4,Raw_Events!$C:$C,"<="&Settings!$B$5)) | G6: =IF($A6="","",COUNTIFS(Raw_Events!$G:$G,"DATE",Raw_Events!$J:$J,$A6,Raw_Events!$C:$C,">="&Settings!$B$4,Raw_Events!$C:$C,"<="&Settings!$B$5)) | H6: =IF($A6="","",COUNTIFS(Raw_Events!$G:$G,"SEX",Raw_Events!$J:$J,$A6,Raw_Events!$C:$C,">="&Settings!$B$4,Raw_Events!$C:$C,"<="&Settings!$B$5)) | I6: =IF($A6="","",COUNTIFS(Raw_Events!$G:$G,"PRO_CONTACT_ADDED",Raw_Events!$J:$J,$A6,Raw_Events!$C:$C,">="&Settings!$B$4,Raw_Events!$C:$C,"<="&Settings!$B$5))
F7: =IF($A7="","",COUNTIFS(Raw_Events!$G:$G,"SOCIAL_MEET",Raw_Events!$J:$J,$A7,Raw_Events!$C:$C,">="&Settings!$B$4,Raw_Events!$C:$C,"<="&Settings!$B$5)) | G7: =IF($A7="","",COUNTIFS(Raw_Events!$G:$G,"DATE",Raw_Events!$J:$J,$A7,Raw_Events!$C:$C,">="&Settings!$B$4,Raw_Events!$C:$C,"<="&Settings!$B$5)) | H7: =IF($A7="","",COUNTIFS(Raw_Events!$G:$G,"SEX",Raw_Events!$J:$J,$A7,Raw_Events!$C:$C,">="&Settings!$B$4,Raw_Events!$C:$C,"<="&Settings!$B$5)) | I7: =IF($A7="","",COUNTIFS(Raw_Events!$G:$G,"PRO_CONTACT_ADDED",Raw_Events!$J:$J,$A7,Raw_Events!$C:$C,">="&Settings!$B$4,Raw_Events!$C:$C,"<="&Settings!$B$5))
F8: =IF($A8="","",COUNTIFS(Raw_Events!$G:$G,"SOCIAL_MEET",Raw_Events!$J:$J,$A8,Raw_Events!$C:$C,">="&Settings!$B$4,Raw_Events!$C:$C,"<="&Settings!$B$5)) | G8: =IF($A8="","",COUNTIFS(Raw_Events!$G:$G,"DATE",Raw_Events!$J:$J,$A8,Raw_Events!$C:$C,">="&Settings!$B$4,Raw_Events!$C:$C,"<="&Settings!$B$5)) | H8: =IF($A8="","",COUNTIFS(Raw_Events!$G:$G,"SEX",Raw_Events!$J:$J,$A8,Raw_Events!$C:$C,">="&Settings!$B$4,Raw_Events!$C:$C,"<="&Settings!$B$5)) | I8: =IF($A8="","",COUNTIFS(Raw_Events!$G:$G,"PRO_CONTACT_ADDED",Raw_Events!$J:$J,$A8,Raw_Events!$C:$C,">="&Settings!$B$4,Raw_Events!$C:$C,"<="&Settings!$B$5))
F9: =IF($A9="","",COUNTIFS(Raw_Events!$G:$G,"SOCIAL_MEET",Raw_Events!$J:$J,$A9,Raw_Events!$C:$C,">="&Settings!$B$4,Raw_Events!$C:$C,"<="&Settings!$B$5)) | G9: =IF($A9="","",COUNTIFS(Raw_Events!$G:$G,"DATE",Raw_Events!$J:$J,$A9,Raw_Events!$C:$C,">="&Settings!$B$4,Raw_Events!$C:$C,"<="&Settings!$B$5)) | H9: =IF($A9="","",COUNTIFS(Raw_Events!$G:$G,"SEX",Raw_Events!$J:$J,$A9,Raw_Events!$C:$C,">="&Settings!$B$4,Raw_Events!$C:$C,"<="&Settings!$B$5)) | I9: =IF($A9="","",COUNTIFS(Raw_Events!$G:$G,"PRO_CONTACT_ADDED",Raw_Events!$J:$J,$A9,Raw_Events!$C:$C,">="&Settings!$B$4,Raw_Events!$C:$C,"<="&Settings!$B$5))
F10: =IF($A10="","",COUNTIFS(Raw_Events!$G:$G,"SOCIAL_MEET",Raw_Events!$J:$J,$A10,Raw_Events!$C:$C,">="&Settings!$B$4,Raw_Events!$C:$C,"<="&Settings!$B$5)) | G10: =IF($A10="","",COUNTIFS(Raw_Events!$G:$G,"DATE",Raw_Events!$J:$J,$A10,Raw_Events!$C:$C,">="&Settings!$B$4,Raw_Events!$C:$C,"<="&Settings!$B$5)) | H10: =IF($A10="","",COUNTIFS(Raw_Events!$G:$G,"SEX",Raw_Events!$J:$J,$A10,Raw_Events!$C:$C,">="&Settings!$B$4,Raw_Events!$C:$C,"<="&Settings!$B$5)) | I10: =IF($A10="","",COUNTIFS(Raw_Events!$G:$G,"PRO_CONTACT_ADDED",Raw_Events!$J:$J,$A10,Raw_Events!$C:$C,">="&Settings!$B$4,Raw_Events!$C:$C,"<="&Settings!$B$5))
F11: =IF($A11="","",COUNTIFS(Raw_Events!$G:$G,"SOCIAL_MEET",Raw_Events!$J:$J,$A11,Raw_Events!$C:$C,">="&Settings!$B$4,Raw_Events!$C:$C,"<="&Settings!$B$5)) | G11: =IF($A11="","",COUNTIFS(Raw_Events!$G:$G,"DATE",Raw_Events!$J:$J,$A11,Raw_Events!$C:$C,">="&Settings!$B$4,Raw_Events!$C:$C,"<="&Settings!$B$5)) | H11: =IF($A11="","",COUNTIFS(Raw_Events!$G:$G,"SEX",Raw_Events!$J:$J,$A11,Raw_Events!$C:$C,">="&Settings!$B$4,Raw_Events!$C:$C,"<="&Settings!$B$5)) | I11: =IF($A11="","",COUNTIFS(Raw_Events!$G:$G,"PRO_CONTACT_ADDED",Raw_Events!$J:$J,$A11,Raw_Events!$C:$C,">="&Settings!$B$4,Raw_Events!$C:$C,"<="&Settings!$B$5))
F12: =IF($A12="","",COUNTIFS(Raw_Events!$G:$G,"SOCIAL_MEET",Raw_Events!$J:$J,$A12,Raw_Events!$C:$C,">="&Settings!$B$4,Raw_Events!$C:$C,"<="&Settings!$B$5)) | G12: =IF($A12="","",COUNTIFS(Raw_Events!$G:$G,"DATE",Raw_Events!$J:$J,$A12,Raw_Events!$C:$C,">="&Settings!$B$4,Raw_Events!$C:$C,"<="&Settings!$B$5)) | H12: =IF($A12="","",COUNTIFS(Raw_Events!$G:$G,"SEX",Raw_Events!$J:$J,$A12,Raw_Events!$C:$C,">="&Settings!$B$4,Raw_Events!$C:$C,"<="&Settings!$B$5)) | I12: =IF($A12="","",COUNTIFS(Raw_Events!$G:$G,"PRO_CONTACT_ADDED",Raw_Events!$J:$J,$A12,Raw_Events!$C:$C,">="&Settings!$B$4,Raw_Events!$C:$C,"<="&Settings!$B$5))
F13: =IF($A13="","",COUNTIFS(Raw_Events!$G:$G,"SOCIAL_MEET",Raw_Events!$J:$J,$A13,Raw_Events!$C:$C,">="&Settings!$B$4,Raw_Events!$C:$C,"<="&Settings!$B$5)) | G13: =IF($A13="","",COUNTIFS(Raw_Events!$G:$G,"DATE",Raw_Events!$J:$J,$A13,Raw_Events!$C:$C,">="&Settings!$B$4,Raw_Events!$C:$C,"<="&Settings!$B$5)) | H13: =IF($A13="","",COUNTIFS(Raw_Events!$G:$G,"SEX",Raw_Events!$J:$J,$A13,Raw_Events!$C:$C,">="&Settings!$B$4,Raw_Events!$C:$C,"<="&Settings!$B$5)) | I13: =IF($A13="","",COUNTIFS(Raw_Events!$G:$G,"PRO_CONTACT_ADDED",Raw_Events!$J:$J,$A13,Raw_Events!$C:$C,">="&Settings!$B$4,Raw_Events!$C:$C,"<="&Settings!$B$5))
F14: =IF($A14="","",COUNTIFS(Raw_Events!$G:$G,"SOCIAL_MEET",Raw_Events!$J:$J,$A14,Raw_Events!$C:$C,">="&Settings!$B$4,Raw_Events!$C:$C,"<="&Settings!$B$5)) | G14: =IF($A14="","",COUNTIFS(Raw_Events!$G:$G,"DATE",Raw_Events!$J:$J,$A14,Raw_Events!$C:$C,">="&Settings!$B$4,Raw_Events!$C:$C,"<="&Settings!$B$5)) | H14: =IF($A14="","",COUNTIFS(Raw_Events!$G:$G,"SEX",Raw_Events!$J:$J,$A14,Raw_Events!$C:$C,">="&Settings!$B$4,Raw_Events!$C:$C,"<="&Settings!$B$5)) | I14: =IF($A14="","",COUNTIFS(Raw_Events!$G:$G,"PRO_CONTACT_ADDED",Raw_Events!$J:$J,$A14,Raw_Events!$C:$C,">="&Settings!$B$4,Raw_Events!$C:$C,"<="&Settings!$B$5))
F15: =IF($A15="","",COUNTIFS(Raw_Events!$G:$G,"SOCIAL_MEET",Raw_Events!$J:$J,$A15,Raw_Events!$C:$C,">="&Settings!$B$4,Raw_Events!$C:$C,"<="&Settings!$B$5)) | G15: =IF($A15="","",COUNTIFS(Raw_Events!$G:$G,"DATE",Raw_Events!$J:$J,$A15,Raw_Events!$C:$C,">="&Settings!$B$4,Raw_Events!$C:$C,"<="&Settings!$B$5)) | H15: =IF($A15="","",COUNTIFS(Raw_Events!$G:$G,"SEX",Raw_Events!$J:$J,$A15,Raw_Events!$C:$C,">="&Settings!$B$4,Raw_Events!$C:$C,"<="&Settings!$B$5)) | I15: =IF($A15="","",COUNTIFS(Raw_Events!$G:$G,"PRO_CONTACT_ADDED",Raw_Events!$J:$J,$A15,Raw_Events!$C:$C,">="&Settings!$B$4,Raw_Events!$C:$C,"<="&Settings!$B$5))
... F500: =IF($A500="","",COUNTIFS(Raw_Events!$G:$G,"SOCIAL_MEET",Raw_Events!$J:$J,$A500,Raw_Events!$C:$C,">="&Settings!$B$4,Raw_Events!$C:$C,"<="&Settings!$B$5)) | G500: =IF($A500="","",COUNTIFS(Raw_Events!$G:$G,"DATE",Raw_Events!$J:$J,$A500,Raw_Events!$C:$C,">="&Settings!$B$4,Raw_Events!$C:$C,"<="&Settings!$B$5)) | H500: =IF($A500="","",COUNTIFS(Raw_Events!$G:$G,"SEX",Raw_Events!$J:$J,$A500,Raw_Events!$C:$C,">="&Settings!$B$4,Raw_Events!$C:$C,"<="&Settings!$B$5)) | I500: =IF($A500="","",COUNTIFS(Raw_Events!$G:$G,"PRO_CONTACT_ADDED",Raw_Events!$J:$J,$A500,Raw_Events!$C:$C,">="&Settings!$B$4,Raw_Events!$C:$C,"<="&Settings!$B$5))

Sheet Raw_Events
A1: Raw event log (append-only). App writes here.
A2: EventID | B2: OccurredAt | C2: Date | D2: WeekStart | E2: MonthStart | F2: Quarter | G2: MetricCode | H2: Value | I2: Unit | J2: PersonID | K2: DrinkTemplateID | L2: StdDrinks | M2: Notes | N2: Tags | O2: Starred | P2: Reviewed | Q2: Source | R2: LoggedAt
C3: =IF($B3="","",INT($B3)) | D3: =IF($C3="","",$C3-WEEKDAY($C3,2)+1) | E3: =IF($C3="","",DATE(YEAR($C3),MONTH($C3),1)) | F3: =IF($C3="","",YEAR($C3)&"-Q"&ROUNDUP(MONTH($C3)/3,0)) | L3: =IF($G3<>"ALCOHOL","",IF($K3="","",$H3*IFERROR(VLOOKUP($K3,Drink_Templates!$A:$G,7,FALSE),0)))
C4: =IF($B4="","",INT($B4)) | D4: =IF($C4="","",$C4-WEEKDAY($C4,2)+1) | E4: =IF($C4="","",DATE(YEAR($C4),MONTH($C4),1)) | F4: =IF($C4="","",YEAR($C4)&"-Q"&ROUNDUP(MONTH($C4)/3,0)) | L4: =IF($G4<>"ALCOHOL","",IF($K4="","",$H4*IFERROR(VLOOKUP($K4,Drink_Templates!$A:$G,7,FALSE),0)))
C5: =IF($B5="","",INT($B5)) | D5: =IF($C5="","",$C5-WEEKDAY($C5,2)+1) | E5: =IF($C5="","",DATE(YEAR($C5),MONTH($C5),1)) | F5: =IF($C5="","",YEAR($C5)&"-Q"&ROUNDUP(MONTH($C5)/3,0)) | L5: =IF($G5<>"ALCOHOL","",IF($K5="","",$H5*IFERROR(VLOOKUP($K5,Drink_Templates!$A:$G,7,FALSE),0)))
C6: =IF($B6="","",INT($B6)) | D6: =IF($C6="","",$C6-WEEKDAY($C6,2)+1) | E6: =IF($C6="","",DATE(YEAR($C6),MONTH($C6),1)) | F6: =IF($C6="","",YEAR($C6)&"-Q"&ROUNDUP(MONTH($C6)/3,0)) | L6: =IF($G6<>"ALCOHOL","",IF($K6="","",$H6*IFERROR(VLOOKUP($K6,Drink_Templates!$A:$G,7,FALSE),0)))
C7: =IF($B7="","",INT($B7)) | D7: =IF($C7="","",$C7-WEEKDAY($C7,2)+1) | E7: =IF($C7="","",DATE(YEAR($C7),MONTH($C7),1)) | F7: =IF($C7="","",YEAR($C7)&"-Q"&ROUNDUP(MONTH($C7)/3,0)) | L7: =IF($G7<>"ALCOHOL","",IF($K7="","",$H7*IFERROR(VLOOKUP($K7,Drink_Templates!$A:$G,7,FALSE),0)))
C8: =IF($B8="","",INT($B8)) | D8: =IF($C8="","",$C8-WEEKDAY($C8,2)+1) | E8: =IF($C8="","",DATE(YEAR($C8),MONTH($C8),1)) | F8: =IF($C8="","",YEAR($C8)&"-Q"&ROUNDUP(MONTH($C8)/3,0)) | L8: =IF($G8<>"ALCOHOL","",IF($K8="","",$H8*IFERROR(VLOOKUP($K8,Drink_Templates!$A:$G,7,FALSE),0)))
C9: =IF($B9="","",INT($B9)) | D9: =IF($C9="","",$C9-WEEKDAY($C9,2)+1) | E9: =IF($C9="","",DATE(YEAR($C9),MONTH($C9),1)) | F9: =IF($C9="","",YEAR($C9)&"-Q"&ROUNDUP(MONTH($C9)/3,0)) | L9: =IF($G9<>"ALCOHOL","",IF($K9="","",$H9*IFERROR(VLOOKUP($K9,Drink_Templates!$A:$G,7,FALSE),0)))
C10: =IF($B10="","",INT($B10)) | D10: =IF($C10="","",$C10-WEEKDAY($C10,2)+1) | E10: =IF($C10="","",DATE(YEAR($C10),MONTH($C10),1)) | F10: =IF($C10="","",YEAR($C10)&"-Q"&ROUNDUP(MONTH($C10)/3,0)) | L10: =IF($G10<>"ALCOHOL","",IF($K10="","",$H10*IFERROR(VLOOKUP($K10,Drink_Templates!$A:$G,7,FALSE),0)))
C11: =IF($B11="","",INT($B11)) | D11: =IF($C11="","",$C11-WEEKDAY($C11,2)+1) | E11: =IF($C11="","",DATE(YEAR($C11),MONTH($C11),1)) | F11: =IF($C11="","",YEAR($C11)&"-Q"&ROUNDUP(MONTH($C11)/3,0)) | L11: =IF($G11<>"ALCOHOL","",IF($K11="","",$H11*IFERROR(VLOOKUP($K11,Drink_Templates!$A:$G,7,FALSE),0)))
C12: =IF($B12="","",INT($B12)) | D12: =IF($C12="","",$C12-WEEKDAY($C12,2)+1) | E12: =IF($C12="","",DATE(YEAR($C12),MONTH($C12),1)) | F12: =IF($C12="","",YEAR($C12)&"-Q"&ROUNDUP(MONTH($C12)/3,0)) | L12: =IF($G12<>"ALCOHOL","",IF($K12="","",$H12*IFERROR(VLOOKUP($K12,Drink_Templates!$A:$G,7,FALSE),0)))
C13: =IF($B13="","",INT($B13)) | D13: =IF($C13="","",$C13-WEEKDAY($C13,2)+1) | E13: =IF($C13="","",DATE(YEAR($C13),MONTH($C13),1)) | F13: =IF($C13="","",YEAR($C13)&"-Q"&ROUNDUP(MONTH($C13)/3,0)) | L13: =IF($G13<>"ALCOHOL","",IF($K13="","",$H13*IFERROR(VLOOKUP($K13,Drink_Templates!$A:$G,7,FALSE),0)))
C14: =IF($B14="","",INT($B14)) | D14: =IF($C14="","",$C14-WEEKDAY($C14,2)+1) | E14: =IF($C14="","",DATE(YEAR($C14),MONTH($C14),1)) | F14: =IF($C14="","",YEAR($C14)&"-Q"&ROUNDUP(MONTH($C14)/3,0)) | L14: =IF($G14<>"ALCOHOL","",IF($K14="","",$H14*IFERROR(VLOOKUP($K14,Drink_Templates!$A:$G,7,FALSE),0)))
... C8002: =IF($B8002="","",INT($B8002)) | D8002: =IF($C8002="","",$C8002-WEEKDAY($C8002,2)+1) | E8002: =IF($C8002="","",DATE(YEAR($C8002),MONTH($C8002),1)) | F8002: =IF($C8002="","",YEAR($C8002)&"-Q"&ROUNDUP(MONTH($C8002)/3,0)) | L8002: =IF($G8002<>"ALCOHOL","",IF($K8002="","",$H8002*IFERROR(VLOOKUP($K8002,Drink_Templates!$A:$G,7,FALSE),0)))

Sheet Raw_Weekly
A1: Weekly inputs (you fill during weekly review)
A2: WeekStart | B2: WorkHours | C2: ExpensesPersonal_RUB | D2: ExcludedRenovation_RUB | E2: NetWorth_RUB(optional) | F2: Notes | G2: Source | H2: DealSpikeFlag(1/0)
A4: 46027 | G4: Manual
A5: 46034 | G5: Manual
A6: 46041 | G6: Manual
A7: 46048 | G7: Manual
A8: 46055 | G8: Manual
A9: 46062 | G9: Manual
A10: 46069 | G10: Manual
A11: 46076 | G11: Manual
A12: 46083 | G12: Manual
A13: 46090 | G13: Manual
A14: 46097 | G14: Manual
A15: 46104 | G15: Manual
... A55: 46384 | G55: Manual

Sheet Body_Metrics
A1: Body metrics (optional, periodic)
A2: Date | B2: (unused) | C2: LeanBodyWeight_kg | D2: BodyFat_%(optional) | E2: Notes | F2: Source

Sheet Daily_Agg
A1: Daily aggregates (app writes totals; sheet computes compliance flags)
A2: Date | B2: Sleep_h | C2: Workouts | D2: Posture_sessions | E2: Posture_met | F2: Mindfulness_min | G2: Mindfulness_day | H2: Cigarettes | I2: Alcohol_std | J2: Unhealthy_meals | K2: Training_min | L2: (unused) | M2: Ideas | N2: Social_meets | O2: Dates | P2: NewActivities | Q2: TravelNights | R2: Notes
A3: 46023 | B3: =SUMIFS(Raw_Events!$H:$H,Raw_Events!$C:$C,$A3,Raw_Events!$G:$G,"SLEEP_HOURS") | C3: =COUNTIFS(Raw_Events!$C:$C,$A3,Raw_Events!$G:$G,"WORKOUT") | D3: =SUMIFS(Raw_Events!$H:$H,Raw_Events!$C:$C,$A3,Raw_Events!$G:$G,"POSTURE_SESSION") | E3: =IF($D3="","",IF($D3>=Settings!$C$17,1,0)) | F3: =SUMIFS(Raw_Events!$H:$H,Raw_Events!$C:$C,$A3,Raw_Events!$G:$G,"MINDFULNESS_MIN") | G3: =IF($F3="","",IF($F3>0,1,0)) | H3: =SUMIFS(Raw_Events!$H:$H,Raw_Events!$C:$C,$A3,Raw_Events!$G:$G,"CIGARETTES") | I3: =SUMIFS(Raw_Events!$L:$L,Raw_Events!$C:$C,$A3,Raw_Events!$G:$G,"ALCOHOL") | J3: =SUMIFS(Raw_Events!$H:$H,Raw_Events!$C:$C,$A3,Raw_Events!$G:$G,"UNHEALTHY_MEAL") | K3: =SUMIFS(Raw_Events!$H:$H,Raw_Events!$C:$C,$A3,Raw_Events!$G:$G,"TRAINING_MIN")+SUMIFS(Raw_Events!$H:$H,Raw_Events!$C:$C,$A3,Raw_Events!$G:$G,"DICTION_TRAINING_MIN") | M3: =SUMIFS(Raw_Events!$H:$H,Raw_Events!$C:$C,$A3,Raw_Events!$G:$G,"IDEA") | N3: =COUNTIFS(Raw_Events!$C:$C,$A3,Raw_Events!$G:$G,"SOCIAL_MEET") | O3: =COUNTIFS(Raw_Events!$C:$C,$A3,Raw_Events!$G:$G,"DATE") | P3: =COUNTIFS(Raw_Events!$C:$C,$A3,Raw_Events!$G:$G,"NEW_ACTIVITY") | Q3: =SUMIFS(Raw_Events!$H:$H,Raw_Events!$C:$C,$A3,Raw_Events!$G:$G,"TRAVEL_NIGHT")
A4: 46024 | B4: =SUMIFS(Raw_Events!$H:$H,Raw_Events!$C:$C,$A4,Raw_Events!$G:$G,"SLEEP_HOURS") | C4: =COUNTIFS(Raw_Events!$C:$C,$A4,Raw_Events!$G:$G,"WORKOUT") | D4: =SUMIFS(Raw_Events!$H:$H,Raw_Events!$C:$C,$A4,Raw_Events!$G:$G,"POSTURE_SESSION") | E4: =IF($D4="","",IF($D4>=Settings!$C$17,1,0)) | F4: =SUMIFS(Raw_Events!$H:$H,Raw_Events!$C:$C,$A4,Raw_Events!$G:$G,"MINDFULNESS_MIN") | G4: =IF($F4="","",IF($F4>0,1,0)) | H4: =SUMIFS(Raw_Events!$H:$H,Raw_Events!$C:$C,$A4,Raw_Events!$G:$G,"CIGARETTES") | I4: =SUMIFS(Raw_Events!$L:$L,Raw_Events!$C:$C,$A4,Raw_Events!$G:$G,"ALCOHOL") | J4: =SUMIFS(Raw_Events!$H:$H,Raw_Events!$C:$C,$A4,Raw_Events!$G:$G,"UNHEALTHY_MEAL") | K4: =SUMIFS(Raw_Events!$H:$H,Raw_Events!$C:$C,$A4,Raw_Events!$G:$G,"TRAINING_MIN")+SUMIFS(Raw_Events!$H:$H,Raw_Events!$C:$C,$A4,Raw_Events!$G:$G,"DICTION_TRAINING_MIN") | M4: =SUMIFS(Raw_Events!$H:$H,Raw_Events!$C:$C,$A4,Raw_Events!$G:$G,"IDEA") | N4: =COUNTIFS(Raw_Events!$C:$C,$A4,Raw_Events!$G:$G,"SOCIAL_MEET") | O4: =COUNTIFS(Raw_Events!$C:$C,$A4,Raw_Events!$G:$G,"DATE") | P4: =COUNTIFS(Raw_Events!$C:$C,$A4,Raw_Events!$G:$G,"NEW_ACTIVITY") | Q4: =SUMIFS(Raw_Events!$H:$H,Raw_Events!$C:$C,$A4,Raw_Events!$G:$G,"TRAVEL_NIGHT")
A5: 46025 | B5: =SUMIFS(Raw_Events!$H:$H,Raw_Events!$C:$C,$A5,Raw_Events!$G:$G,"SLEEP_HOURS") | C5: =COUNTIFS(Raw_Events!$C:$C,$A5,Raw_Events!$G:$G,"WORKOUT") | D5: =SUMIFS(Raw_Events!$H:$H,Raw_Events!$C:$C,$A5,Raw_Events!$G:$G,"POSTURE_SESSION") | E5: =IF($D5="","",IF($D5>=Settings!$C$17,1,0)) | F5: =SUMIFS(Raw_Events!$H:$H,Raw_Events!$C:$C,$A5,Raw_Events!$G:$G,"MINDFULNESS_MIN") | G5: =IF($F5="","",IF($F5>0,1,0)) | H5: =SUMIFS(Raw_Events!$H:$H,Raw_Events!$C:$C,$A5,Raw_Events!$G:$G,"CIGARETTES") | I5: =SUMIFS(Raw_Events!$L:$L,Raw_Events!$C:$C,$A5,Raw_Events!$G:$G,"ALCOHOL") | J5: =SUMIFS(Raw_Events!$H:$H,Raw_Events!$C:$C,$A5,Raw_Events!$G:$G,"UNHEALTHY_MEAL") | K5: =SUMIFS(Raw_Events!$H:$H,Raw_Events!$C:$C,$A5,Raw_Events!$G:$G,"TRAINING_MIN")+SUMIFS(Raw_Events!$H:$H,Raw_Events!$C:$C,$A5,Raw_Events!$G:$G,"DICTION_TRAINING_MIN") | M5: =SUMIFS(Raw_Events!$H:$H,Raw_Events!$C:$C,$A5,Raw_Events!$G:$G,"IDEA") | N5: =COUNTIFS(Raw_Events!$C:$C,$A5,Raw_Events!$G:$G,"SOCIAL_MEET") | O5: =COUNTIFS(Raw_Events!$C:$C,$A5,Raw_Events!$G:$G,"DATE") | P5: =COUNTIFS(Raw_Events!$C:$C,$A5,Raw_Events!$G:$G,"NEW_ACTIVITY") | Q5: =SUMIFS(Raw_Events!$H:$H,Raw_Events!$C:$C,$A5,Raw_Events!$G:$G,"TRAVEL_NIGHT")
A6: 46026 | B6: =SUMIFS(Raw_Events!$H:$H,Raw_Events!$C:$C,$A6,Raw_Events!$G:$G,"SLEEP_HOURS") | C6: =COUNTIFS(Raw_Events!$C:$C,$A6,Raw_Events!$G:$G,"WORKOUT") | D6: =SUMIFS(Raw_Events!$H:$H,Raw_Events!$C:$C,$A6,Raw_Events!$G:$G,"POSTURE_SESSION") | E6: =IF($D6="","",IF($D6>=Settings!$C$17,1,0)) | F6: =SUMIFS(Raw_Events!$H:$H,Raw_Events!$C:$C,$A6,Raw_Events!$G:$G,"MINDFULNESS_MIN") | G6: =IF($F6="","",IF($F6>0,1,0)) | H6: =SUMIFS(Raw_Events!$H:$H,Raw_Events!$C:$C,$A6,Raw_Events!$G:$G,"CIGARETTES") | I6: =SUMIFS(Raw_Events!$L:$L,Raw_Events!$C:$C,$A6,Raw_Events!$G:$G,"ALCOHOL") | J6: =SUMIFS(Raw_Events!$H:$H,Raw_Events!$C:$C,$A6,Raw_Events!$G:$G,"UNHEALTHY_MEAL") | K6: =SUMIFS(Raw_Events!$H:$H,Raw_Events!$C:$C,$A6,Raw_Events!$G:$G,"TRAINING_MIN")+SUMIFS(Raw_Events!$H:$H,Raw_Events!$C:$C,$A6,Raw_Events!$G:$G,"DICTION_TRAINING_MIN") | M6: =SUMIFS(Raw_Events!$H:$H,Raw_Events!$C:$C,$A6,Raw_Events!$G:$G,"IDEA") | N6: =COUNTIFS(Raw_Events!$C:$C,$A6,Raw_Events!$G:$G,"SOCIAL_MEET") | O6: =COUNTIFS(Raw_Events!$C:$C,$A6,Raw_Events!$G:$G,"DATE") | P6: =COUNTIFS(Raw_Events!$C:$C,$A6,Raw_Events!$G:$G,"NEW_ACTIVITY") | Q6: =SUMIFS(Raw_Events!$H:$H,Raw_Events!$C:$C,$A6,Raw_Events!$G:$G,"TRAVEL_NIGHT")
A7: 46027 | B7: =SUMIFS(Raw_Events!$H:$H,Raw_Events!$C:$C,$A7,Raw_Events!$G:$G,"SLEEP_HOURS") | C7: =COUNTIFS(Raw_Events!$C:$C,$A7,Raw_Events!$G:$G,"WORKOUT") | D7: =SUMIFS(Raw_Events!$H:$H,Raw_Events!$C:$C,$A7,Raw_Events!$G:$G,"POSTURE_SESSION") | E7: =IF($D7="","",IF($D7>=Settings!$C$17,1,0)) | F7: =SUMIFS(Raw_Events!$H:$H,Raw_Events!$C:$C,$A7,Raw_Events!$G:$G,"MINDFULNESS_MIN") | G7: =IF($F7="","",IF($F7>0,1,0)) | H7: =SUMIFS(Raw_Events!$H:$H,Raw_Events!$C:$C,$A7,Raw_Events!$G:$G,"CIGARETTES") | I7: =SUMIFS(Raw_Events!$L:$L,Raw_Events!$C:$C,$A7,Raw_Events!$G:$G,"ALCOHOL") | J7: =SUMIFS(Raw_Events!$H:$H,Raw_Events!$C:$C,$A7,Raw_Events!$G:$G,"UNHEALTHY_MEAL") | K7: =SUMIFS(Raw_Events!$H:$H,Raw_Events!$C:$C,$A7,Raw_Events!$G:$G,"TRAINING_MIN")+SUMIFS(Raw_Events!$H:$H,Raw_Events!$C:$C,$A7,Raw_Events!$G:$G,"DICTION_TRAINING_MIN") | M7: =SUMIFS(Raw_Events!$H:$H,Raw_Events!$C:$C,$A7,Raw_Events!$G:$G,"IDEA") | N7: =COUNTIFS(Raw_Events!$C:$C,$A7,Raw_Events!$G:$G,"SOCIAL_MEET") | O7: =COUNTIFS(Raw_Events!$C:$C,$A7,Raw_Events!$G:$G,"DATE") | P7: =COUNTIFS(Raw_Events!$C:$C,$A7,Raw_Events!$G:$G,"NEW_ACTIVITY") | Q7: =SUMIFS(Raw_Events!$H:$H,Raw_Events!$C:$C,$A7,Raw_Events!$G:$G,"TRAVEL_NIGHT")
A8: 46028 | B8: =SUMIFS(Raw_Events!$H:$H,Raw_Events!$C:$C,$A8,Raw_Events!$G:$G,"SLEEP_HOURS") | C8: =COUNTIFS(Raw_Events!$C:$C,$A8,Raw_Events!$G:$G,"WORKOUT") | D8: =SUMIFS(Raw_Events!$H:$H,Raw_Events!$C:$C,$A8,Raw_Events!$G:$G,"POSTURE_SESSION") | E8: =IF($D8="","",IF($D8>=Settings!$C$17,1,0)) | F8: =SUMIFS(Raw_Events!$H:$H,Raw_Events!$C:$C,$A8,Raw_Events!$G:$G,"MINDFULNESS_MIN") | G8: =IF($F8="","",IF($F8>0,1,0)) | H8: =SUMIFS(Raw_Events!$H:$H,Raw_Events!$C:$C,$A8,Raw_Events!$G:$G,"CIGARETTES") | I8: =SUMIFS(Raw_Events!$L:$L,Raw_Events!$C:$C,$A8,Raw_Events!$G:$G,"ALCOHOL") | J8: =SUMIFS(Raw_Events!$H:$H,Raw_Events!$C:$C,$A8,Raw_Events!$G:$G,"UNHEALTHY_MEAL") | K8: =SUMIFS(Raw_Events!$H:$H,Raw_Events!$C:$C,$A8,Raw_Events!$G:$G,"TRAINING_MIN")+SUMIFS(Raw_Events!$H:$H,Raw_Events!$C:$C,$A8,Raw_Events!$G:$G,"DICTION_TRAINING_MIN") | M8: =SUMIFS(Raw_Events!$H:$H,Raw_Events!$C:$C,$A8,Raw_Events!$G:$G,"IDEA") | N8: =COUNTIFS(Raw_Events!$C:$C,$A8,Raw_Events!$G:$G,"SOCIAL_MEET") | O8: =COUNTIFS(Raw_Events!$C:$C,$A8,Raw_Events!$G:$G,"DATE") | P8: =COUNTIFS(Raw_Events!$C:$C,$A8,Raw_Events!$G:$G,"NEW_ACTIVITY") | Q8: =SUMIFS(Raw_Events!$H:$H,Raw_Events!$C:$C,$A8,Raw_Events!$G:$G,"TRAVEL_NIGHT")
A9: 46029 | B9: =SUMIFS(Raw_Events!$H:$H,Raw_Events!$C:$C,$A9,Raw_Events!$G:$G,"SLEEP_HOURS") | C9: =COUNTIFS(Raw_Events!$C:$C,$A9,Raw_Events!$G:$G,"WORKOUT") | D9: =SUMIFS(Raw_Events!$H:$H,Raw_Events!$C:$C,$A9,Raw_Events!$G:$G,"POSTURE_SESSION") | E9: =IF($D9="","",IF($D9>=Settings!$C$17,1,0)) | F9: =SUMIFS(Raw_Events!$H:$H,Raw_Events!$C:$C,$A9,Raw_Events!$G:$G,"MINDFULNESS_MIN") | G9: =IF($F9="","",IF($F9>0,1,0)) | H9: =SUMIFS(Raw_Events!$H:$H,Raw_Events!$C:$C,$A9,Raw_Events!$G:$G,"CIGARETTES") | I9: =SUMIFS(Raw_Events!$L:$L,Raw_Events!$C:$C,$A9,Raw_Events!$G:$G,"ALCOHOL") | J9: =SUMIFS(Raw_Events!$H:$H,Raw_Events!$C:$C,$A9,Raw_Events!$G:$G,"UNHEALTHY_MEAL") | K9: =SUMIFS(Raw_Events!$H:$H,Raw_Events!$C:$C,$A9,Raw_Events!$G:$G,"TRAINING_MIN")+SUMIFS(Raw_Events!$H:$H,Raw_Events!$C:$C,$A9,Raw_Events!$G:$G,"DICTION_TRAINING_MIN") | M9: =SUMIFS(Raw_Events!$H:$H,Raw_Events!$C:$C,$A9,Raw_Events!$G:$G,"IDEA") | N9: =COUNTIFS(Raw_Events!$C:$C,$A9,Raw_Events!$G:$G,"SOCIAL_MEET") | O9: =COUNTIFS(Raw_Events!$C:$C,$A9,Raw_Events!$G:$G,"DATE") | P9: =COUNTIFS(Raw_Events!$C:$C,$A9,Raw_Events!$G:$G,"NEW_ACTIVITY") | Q9: =SUMIFS(Raw_Events!$H:$H,Raw_Events!$C:$C,$A9,Raw_Events!$G:$G,"TRAVEL_NIGHT")
A10: 46030 | B10: =SUMIFS(Raw_Events!$H:$H,Raw_Events!$C:$C,$A10,Raw_Events!$G:$G,"SLEEP_HOURS") | C10: =COUNTIFS(Raw_Events!$C:$C,$A10,Raw_Events!$G:$G,"WORKOUT") | D10: =SUMIFS(Raw_Events!$H:$H,Raw_Events!$C:$C,$A10,Raw_Events!$G:$G,"POSTURE_SESSION") | E10: =IF($D10="","",IF($D10>=Settings!$C$17,1,0)) | F10: =SUMIFS(Raw_Events!$H:$H,Raw_Events!$C:$C,$A10,Raw_Events!$G:$G,"MINDFULNESS_MIN") | G10: =IF($F10="","",IF($F10>0,1,0)) | H10: =SUMIFS(Raw_Events!$H:$H,Raw_Events!$C:$C,$A10,Raw_Events!$G:$G,"CIGARETTES") | I10: =SUMIFS(Raw_Events!$L:$L,Raw_Events!$C:$C,$A10,Raw_Events!$G:$G,"ALCOHOL") | J10: =SUMIFS(Raw_Events!$H:$H,Raw_Events!$C:$C,$A10,Raw_Events!$G:$G,"UNHEALTHY_MEAL") | K10: =SUMIFS(Raw_Events!$H:$H,Raw_Events!$C:$C,$A10,Raw_Events!$G:$G,"TRAINING_MIN")+SUMIFS(Raw_Events!$H:$H,Raw_Events!$C:$C,$A10,Raw_Events!$G:$G,"DICTION_TRAINING_MIN") | M10: =SUMIFS(Raw_Events!$H:$H,Raw_Events!$C:$C,$A10,Raw_Events!$G:$G,"IDEA") | N10: =COUNTIFS(Raw_Events!$C:$C,$A10,Raw_Events!$G:$G,"SOCIAL_MEET") | O10: =COUNTIFS(Raw_Events!$C:$C,$A10,Raw_Events!$G:$G,"DATE") | P10: =COUNTIFS(Raw_Events!$C:$C,$A10,Raw_Events!$G:$G,"NEW_ACTIVITY") | Q10: =SUMIFS(Raw_Events!$H:$H,Raw_Events!$C:$C,$A10,Raw_Events!$G:$G,"TRAVEL_NIGHT")
A11: 46031 | B11: =SUMIFS(Raw_Events!$H:$H,Raw_Events!$C:$C,$A11,Raw_Events!$G:$G,"SLEEP_HOURS") | C11: =COUNTIFS(Raw_Events!$C:$C,$A11,Raw_Events!$G:$G,"WORKOUT") | D11: =SUMIFS(Raw_Events!$H:$H,Raw_Events!$C:$C,$A11,Raw_Events!$G:$G,"POSTURE_SESSION") | E11: =IF($D11="","",IF($D11>=Settings!$C$17,1,0)) | F11: =SUMIFS(Raw_Events!$H:$H,Raw_Events!$C:$C,$A11,Raw_Events!$G:$G,"MINDFULNESS_MIN") | G11: =IF($F11="","",IF($F11>0,1,0)) | H11: =SUMIFS(Raw_Events!$H:$H,Raw_Events!$C:$C,$A11,Raw_Events!$G:$G,"CIGARETTES") | I11: =SUMIFS(Raw_Events!$L:$L,Raw_Events!$C:$C,$A11,Raw_Events!$G:$G,"ALCOHOL") | J11: =SUMIFS(Raw_Events!$H:$H,Raw_Events!$C:$C,$A11,Raw_Events!$G:$G,"UNHEALTHY_MEAL") | K11: =SUMIFS(Raw_Events!$H:$H,Raw_Events!$C:$C,$A11,Raw_Events!$G:$G,"TRAINING_MIN")+SUMIFS(Raw_Events!$H:$H,Raw_Events!$C:$C,$A11,Raw_Events!$G:$G,"DICTION_TRAINING_MIN") | M11: =SUMIFS(Raw_Events!$H:$H,Raw_Events!$C:$C,$A11,Raw_Events!$G:$G,"IDEA") | N11: =COUNTIFS(Raw_Events!$C:$C,$A11,Raw_Events!$G:$G,"SOCIAL_MEET") | O11: =COUNTIFS(Raw_Events!$C:$C,$A11,Raw_Events!$G:$G,"DATE") | P11: =COUNTIFS(Raw_Events!$C:$C,$A11,Raw_Events!$G:$G,"NEW_ACTIVITY") | Q11: =SUMIFS(Raw_Events!$H:$H,Raw_Events!$C:$C,$A11,Raw_Events!$G:$G,"TRAVEL_NIGHT")
A12: 46032 | B12: =SUMIFS(Raw_Events!$H:$H,Raw_Events!$C:$C,$A12,Raw_Events!$G:$G,"SLEEP_HOURS") | C12: =COUNTIFS(Raw_Events!$C:$C,$A12,Raw_Events!$G:$G,"WORKOUT") | D12: =SUMIFS(Raw_Events!$H:$H,Raw_Events!$C:$C,$A12,Raw_Events!$G:$G,"POSTURE_SESSION") | E12: =IF($D12="","",IF($D12>=Settings!$C$17,1,0)) | F12: =SUMIFS(Raw_Events!$H:$H,Raw_Events!$C:$C,$A12,Raw_Events!$G:$G,"MINDFULNESS_MIN") | G12: =IF($F12="","",IF($F12>0,1,0)) | H12: =SUMIFS(Raw_Events!$H:$H,Raw_Events!$C:$C,$A12,Raw_Events!$G:$G,"CIGARETTES") | I12: =SUMIFS(Raw_Events!$L:$L,Raw_Events!$C:$C,$A12,Raw_Events!$G:$G,"ALCOHOL") | J12: =SUMIFS(Raw_Events!$H:$H,Raw_Events!$C:$C,$A12,Raw_Events!$G:$G,"UNHEALTHY_MEAL") | K12: =SUMIFS(Raw_Events!$H:$H,Raw_Events!$C:$C,$A12,Raw_Events!$G:$G,"TRAINING_MIN")+SUMIFS(Raw_Events!$H:$H,Raw_Events!$C:$C,$A12,Raw_Events!$G:$G,"DICTION_TRAINING_MIN") | M12: =SUMIFS(Raw_Events!$H:$H,Raw_Events!$C:$C,$A12,Raw_Events!$G:$G,"IDEA") | N12: =COUNTIFS(Raw_Events!$C:$C,$A12,Raw_Events!$G:$G,"SOCIAL_MEET") | O12: =COUNTIFS(Raw_Events!$C:$C,$A12,Raw_Events!$G:$G,"DATE") | P12: =COUNTIFS(Raw_Events!$C:$C,$A12,Raw_Events!$G:$G,"NEW_ACTIVITY") | Q12: =SUMIFS(Raw_Events!$H:$H,Raw_Events!$C:$C,$A12,Raw_Events!$G:$G,"TRAVEL_NIGHT")
A13: 46033 | B13: =SUMIFS(Raw_Events!$H:$H,Raw_Events!$C:$C,$A13,Raw_Events!$G:$G,"SLEEP_HOURS") | C13: =COUNTIFS(Raw_Events!$C:$C,$A13,Raw_Events!$G:$G,"WORKOUT") | D13: =SUMIFS(Raw_Events!$H:$H,Raw_Events!$C:$C,$A13,Raw_Events!$G:$G,"POSTURE_SESSION") | E13: =IF($D13="","",IF($D13>=Settings!$C$17,1,0)) | F13: =SUMIFS(Raw_Events!$H:$H,Raw_Events!$C:$C,$A13,Raw_Events!$G:$G,"MINDFULNESS_MIN") | G13: =IF($F13="","",IF($F13>0,1,0)) | H13: =SUMIFS(Raw_Events!$H:$H,Raw_Events!$C:$C,$A13,Raw_Events!$G:$G,"CIGARETTES") | I13: =SUMIFS(Raw_Events!$L:$L,Raw_Events!$C:$C,$A13,Raw_Events!$G:$G,"ALCOHOL") | J13: =SUMIFS(Raw_Events!$H:$H,Raw_Events!$C:$C,$A13,Raw_Events!$G:$G,"UNHEALTHY_MEAL") | K13: =SUMIFS(Raw_Events!$H:$H,Raw_Events!$C:$C,$A13,Raw_Events!$G:$G,"TRAINING_MIN")+SUMIFS(Raw_Events!$H:$H,Raw_Events!$C:$C,$A13,Raw_Events!$G:$G,"DICTION_TRAINING_MIN") | M13: =SUMIFS(Raw_Events!$H:$H,Raw_Events!$C:$C,$A13,Raw_Events!$G:$G,"IDEA") | N13: =COUNTIFS(Raw_Events!$C:$C,$A13,Raw_Events!$G:$G,"SOCIAL_MEET") | O13: =COUNTIFS(Raw_Events!$C:$C,$A13,Raw_Events!$G:$G,"DATE") | P13: =COUNTIFS(Raw_Events!$C:$C,$A13,Raw_Events!$G:$G,"NEW_ACTIVITY") | Q13: =SUMIFS(Raw_Events!$H:$H,Raw_Events!$C:$C,$A13,Raw_Events!$G:$G,"TRAVEL_NIGHT")
A14: 46034 | B14: =SUMIFS(Raw_Events!$H:$H,Raw_Events!$C:$C,$A14,Raw_Events!$G:$G,"SLEEP_HOURS") | C14: =COUNTIFS(Raw_Events!$C:$C,$A14,Raw_Events!$G:$G,"WORKOUT") | D14: =SUMIFS(Raw_Events!$H:$H,Raw_Events!$C:$C,$A14,Raw_Events!$G:$G,"POSTURE_SESSION") | E14: =IF($D14="","",IF($D14>=Settings!$C$17,1,0)) | F14: =SUMIFS(Raw_Events!$H:$H,Raw_Events!$C:$C,$A14,Raw_Events!$G:$G,"MINDFULNESS_MIN") | G14: =IF($F14="","",IF($F14>0,1,0)) | H14: =SUMIFS(Raw_Events!$H:$H,Raw_Events!$C:$C,$A14,Raw_Events!$G:$G,"CIGARETTES") | I14: =SUMIFS(Raw_Events!$L:$L,Raw_Events!$C:$C,$A14,Raw_Events!$G:$G,"ALCOHOL") | J14: =SUMIFS(Raw_Events!$H:$H,Raw_Events!$C:$C,$A14,Raw_Events!$G:$G,"UNHEALTHY_MEAL") | K14: =SUMIFS(Raw_Events!$H:$H,Raw_Events!$C:$C,$A14,Raw_Events!$G:$G,"TRAINING_MIN")+SUMIFS(Raw_Events!$H:$H,Raw_Events!$C:$C,$A14,Raw_Events!$G:$G,"DICTION_TRAINING_MIN") | M14: =SUMIFS(Raw_Events!$H:$H,Raw_Events!$C:$C,$A14,Raw_Events!$G:$G,"IDEA") | N14: =COUNTIFS(Raw_Events!$C:$C,$A14,Raw_Events!$G:$G,"SOCIAL_MEET") | O14: =COUNTIFS(Raw_Events!$C:$C,$A14,Raw_Events!$G:$G,"DATE") | P14: =COUNTIFS(Raw_Events!$C:$C,$A14,Raw_Events!$G:$G,"NEW_ACTIVITY") | Q14: =SUMIFS(Raw_Events!$H:$H,Raw_Events!$C:$C,$A14,Raw_Events!$G:$G,"TRAVEL_NIGHT")
... A367: 46387 | B367: =SUMIFS(Raw_Events!$H:$H,Raw_Events!$C:$C,$A367,Raw_Events!$G:$G,"SLEEP_HOURS") | C367: =COUNTIFS(Raw_Events!$C:$C,$A367,Raw_Events!$G:$G,"WORKOUT") | D367: =SUMIFS(Raw_Events!$H:$H,Raw_Events!$C:$C,$A367,Raw_Events!$G:$G,"POSTURE_SESSION") | E367: =IF($D367="","",IF($D367>=Settings!$C$17,1,0)) | F367: =SUMIFS(Raw_Events!$H:$H,Raw_Events!$C:$C,$A367,Raw_Events!$G:$G,"MINDFULNESS_MIN") | G367: =IF($F367="","",IF($F367>0,1,0)) | H367: =SUMIFS(Raw_Events!$H:$H,Raw_Events!$C:$C,$A367,Raw_Events!$G:$G,"CIGARETTES") | I367: =SUMIFS(Raw_Events!$L:$L,Raw_Events!$C:$C,$A367,Raw_Events!$G:$G,"ALCOHOL") | J367: =SUMIFS(Raw_Events!$H:$H,Raw_Events!$C:$C,$A367,Raw_Events!$G:$G,"UNHEALTHY_MEAL") | K367: =SUMIFS(Raw_Events!$H:$H,Raw_Events!$C:$C,$A367,Raw_Events!$G:$G,"TRAINING_MIN")+SUMIFS(Raw_Events!$H:$H,Raw_Events!$C:$C,$A367,Raw_Events!$G:$G,"DICTION_TRAINING_MIN") | M367: =SUMIFS(Raw_Events!$H:$H,Raw_Events!$C:$C,$A367,Raw_Events!$G:$G,"IDEA") | N367: =COUNTIFS(Raw_Events!$C:$C,$A367,Raw_Events!$G:$G,"SOCIAL_MEET") | O367: =COUNTIFS(Raw_Events!$C:$C,$A367,Raw_Events!$G:$G,"DATE") | P367: =COUNTIFS(Raw_Events!$C:$C,$A367,Raw_Events!$G:$G,"NEW_ACTIVITY") | Q367: =SUMIFS(Raw_Events!$H:$H,Raw_Events!$C:$C,$A367,Raw_Events!$G:$G,"TRAVEL_NIGHT")

Sheet Weekly_Agg
A1: Weekly aggregates (app fills inputs; sheet computes compliance flags)
A2: WeekStart | B2: WorkHours | C2: ExpensesPersonal_RUB | D2: ExcludedRenovation_RUB | E2: BusyWeek(>=60) | F2: WorkHours_met(<=55) | G2: Expenses_met(<=175k) | H2: SocialEvents | I2: Dates | J2: TrainingSessions | K2: Training_min | L2: Ideas | M2: Mindfulness_min | N2: Mindfulness_days | O2: Posture_days_met | P2: Alcohol_std | Q2: Cigarettes | R2: Unhealthy_meals | S2: Workouts | T2: NetWorth_RUB | U2: NewActivities | V2: TravelNights | W2: SpikeMinimum_met? | X2: OriginationActions | Y2: Origination_met(>=1) | Z2: WorkoutsSkipped | AA2: CommunitySessions | AB2: HostedEvents | AC2: IdeaStars | AD2: Trigger_LowSocial_2w | AE2: Trigger_LowDates_2w | AF2: BusyWeekFloorNeeded? | AG2: Trigger_DealSpike_2w | AH2: Trigger_IdeaNoReview | AI2: DeepWork_hours | AJ2: Education_hours | AK2: Hobby_hours | AL2: PartnerQualityTime | AM2: InvestmentCoverage_pct
